2025-08-15 03:02:50,355 - chromadb.telemetry.product.posthog - ERROR - Failed to send telemetry event ClientStartEvent: capture() takes 1 positional argument but 3 were given
2025-08-15 03:02:50,356 - sentence_transformers.SentenceTransformer - INFO - Use pytorch device_name: cpu
2025-08-15 03:02:50,357 - sentence_transformers.SentenceTransformer - INFO - Load pretrained SentenceTransformer: all-MiniLM-L6-v2
2025-08-15 03:02:55,980 - chromadb.telemetry.product.posthog - ERROR - Failed to send telemetry event ClientCreateCollectionEvent: capture() takes 1 positional argument but 3 were given
2025-08-15 03:02:55,992 - chromadb.telemetry.product.posthog - ERROR - Failed to send telemetry event ClientCreateCollectionEvent: capture() takes 1 positional argument but 3 were given
2025-08-15 03:02:56,005 - chromadb.telemetry.product.posthog - ERROR - Failed to send telemetry event ClientCreateCollectionEvent: capture() takes 1 positional argument but 3 were given
2025-08-15 03:02:56,421 - chromadb.telemetry.product.posthog - ERROR - Failed to send telemetry event CollectionAddEvent: capture() takes 1 positional argument but 3 were given
2025-08-15 03:02:56,598 - chromadb.telemetry.product.posthog - ERROR - Failed to send telemetry event CollectionAddEvent: capture() takes 1 positional argument but 3 were given
2025-08-15 03:04:45,145 - chromadb.telemetry.product.posthog - ERROR - Failed to send telemetry event ClientStartEvent: capture() takes 1 positional argument but 3 were given
2025-08-15 03:04:45,146 - sentence_transformers.SentenceTransformer - INFO - Use pytorch device_name: cpu
2025-08-15 03:04:45,147 - sentence_transformers.SentenceTransformer - INFO - Load pretrained SentenceTransformer: all-MiniLM-L6-v2
2025-08-15 03:05:37,570 - chromadb.telemetry.product.posthog - ERROR - Failed to send telemetry event ClientStartEvent: capture() takes 1 positional argument but 3 were given
2025-08-15 03:05:37,572 - sentence_transformers.SentenceTransformer - INFO - Use pytorch device_name: cpu
2025-08-15 03:05:37,572 - sentence_transformers.SentenceTransformer - INFO - Load pretrained SentenceTransformer: all-MiniLM-L6-v2
2025-08-15 03:05:42,471 - services.task_queue - INFO - Task queue started
2025-08-15 03:05:42,474 - services.task_queue - INFO - Periodic tasks completed at 2025-08-15 03:05:42.474077
2025-08-15 03:06:34,046 - passlib.handlers.bcrypt - WARNING - (trapped) error reading bcrypt version
Traceback (most recent call last):
  File "S:\capitalone\project\venv\Lib\site-packages\passlib\handlers\bcrypt.py", line 620, in _load_backend_mixin
    version = _bcrypt.__about__.__version__
              ^^^^^^^^^^^^^^^^^
AttributeError: module 'bcrypt' has no attribute '__about__'
2025-08-15 03:07:38,289 - chromadb.telemetry.product.posthog - ERROR - Failed to send telemetry event CollectionQueryEvent: capture() takes 1 positional argument but 3 were given
2025-08-15 03:07:38,361 - chromadb.telemetry.product.posthog - ERROR - Failed to send telemetry event CollectionQueryEvent: capture() takes 1 positional argument but 3 were given
2025-08-15 03:07:38,435 - chromadb.telemetry.product.posthog - ERROR - Failed to send telemetry event CollectionQueryEvent: capture() takes 1 positional argument but 3 were given
2025-08-15 03:07:41,223 - services.error_handler - ERROR - Error in weather_current: 401 Client Error: Unauthorized for url: http://api.openweathermap.org/data/2.5/weather?q=Davanagere%2C+Karnataka&appid=your_openweather_api_key_here&units=metric
2025-08-15 03:07:41,224 - services.error_handler - ERROR - Traceback: Traceback (most recent call last):
  File "S:\capitalone\project\web_app\..\services\weather.py", line 42, in get_current_weather
    response.raise_for_status()
    ~~~~~~~~~~~~~~~~~~~~~~~~~^^
  File "S:\capitalone\project\venv\Lib\site-packages\requests\models.py", line 1026, in raise_for_status
    raise HTTPError(http_error_msg, response=self)
requests.exceptions.HTTPError: 401 Client Error: Unauthorized for url: http://api.openweathermap.org/data/2.5/weather?q=Davanagere%2C+Karnataka&appid=your_openweather_api_key_here&units=metric

2025-08-15 03:07:41,416 - services.error_handler - ERROR - Error in weather_forecast: 401 Client Error: Unauthorized for url: http://api.openweathermap.org/data/2.5/forecast?q=Davanagere%2C+Karnataka&appid=your_openweather_api_key_here&units=metric&cnt=40
2025-08-15 03:07:41,417 - services.error_handler - ERROR - Traceback: Traceback (most recent call last):
  File "S:\capitalone\project\web_app\..\services\weather.py", line 90, in get_weather_forecast
    response.raise_for_status()
    ~~~~~~~~~~~~~~~~~~~~~~~~~^^
  File "S:\capitalone\project\venv\Lib\site-packages\requests\models.py", line 1026, in raise_for_status
    raise HTTPError(http_error_msg, response=self)
requests.exceptions.HTTPError: 401 Client Error: Unauthorized for url: http://api.openweathermap.org/data/2.5/forecast?q=Davanagere%2C+Karnataka&appid=your_openweather_api_key_here&units=metric&cnt=40

2025-08-15 03:20:24,813 - services.error_handler - ERROR - Error in weather_current: 401 Client Error: Unauthorized for url: http://api.openweathermap.org/data/2.5/weather?q=panjab&appid=your_openweather_api_key_here&units=metric
2025-08-15 03:20:24,813 - services.error_handler - ERROR - Traceback: Traceback (most recent call last):
  File "S:\capitalone\project\web_app\..\services\weather.py", line 42, in get_current_weather
    response.raise_for_status()
    ~~~~~~~~~~~~~~~~~~~~~~~~~^^
  File "S:\capitalone\project\venv\Lib\site-packages\requests\models.py", line 1026, in raise_for_status
    raise HTTPError(http_error_msg, response=self)
requests.exceptions.HTTPError: 401 Client Error: Unauthorized for url: http://api.openweathermap.org/data/2.5/weather?q=panjab&appid=your_openweather_api_key_here&units=metric

2025-08-15 03:20:24,994 - services.error_handler - ERROR - Error in weather_forecast: 401 Client Error: Unauthorized for url: http://api.openweathermap.org/data/2.5/forecast?q=panjab&appid=your_openweather_api_key_here&units=metric&cnt=40
2025-08-15 03:20:24,995 - services.error_handler - ERROR - Traceback: Traceback (most recent call last):
  File "S:\capitalone\project\web_app\..\services\weather.py", line 90, in get_weather_forecast
    response.raise_for_status()
    ~~~~~~~~~~~~~~~~~~~~~~~~~^^
  File "S:\capitalone\project\venv\Lib\site-packages\requests\models.py", line 1026, in raise_for_status
    raise HTTPError(http_error_msg, response=self)
requests.exceptions.HTTPError: 401 Client Error: Unauthorized for url: http://api.openweathermap.org/data/2.5/forecast?q=panjab&appid=your_openweather_api_key_here&units=metric&cnt=40

2025-08-15 03:20:44,412 - services.error_handler - ERROR - Error in weather_current: 401 Client Error: Unauthorized for url: http://api.openweathermap.org/data/2.5/weather?q=abcd&appid=your_openweather_api_key_here&units=metric
2025-08-15 03:20:44,413 - services.error_handler - ERROR - Traceback: Traceback (most recent call last):
  File "S:\capitalone\project\web_app\..\services\weather.py", line 42, in get_current_weather
    response.raise_for_status()
    ~~~~~~~~~~~~~~~~~~~~~~~~~^^
  File "S:\capitalone\project\venv\Lib\site-packages\requests\models.py", line 1026, in raise_for_status
    raise HTTPError(http_error_msg, response=self)
requests.exceptions.HTTPError: 401 Client Error: Unauthorized for url: http://api.openweathermap.org/data/2.5/weather?q=abcd&appid=your_openweather_api_key_here&units=metric

2025-08-15 03:20:44,587 - services.error_handler - ERROR - Error in weather_forecast: 401 Client Error: Unauthorized for url: http://api.openweathermap.org/data/2.5/forecast?q=abcd&appid=your_openweather_api_key_here&units=metric&cnt=40
2025-08-15 03:20:44,588 - services.error_handler - ERROR - Traceback: Traceback (most recent call last):
  File "S:\capitalone\project\web_app\..\services\weather.py", line 90, in get_weather_forecast
    response.raise_for_status()
    ~~~~~~~~~~~~~~~~~~~~~~~~~^^
  File "S:\capitalone\project\venv\Lib\site-packages\requests\models.py", line 1026, in raise_for_status
    raise HTTPError(http_error_msg, response=self)
requests.exceptions.HTTPError: 401 Client Error: Unauthorized for url: http://api.openweathermap.org/data/2.5/forecast?q=abcd&appid=your_openweather_api_key_here&units=metric&cnt=40

2025-08-15 03:21:13,403 - services.error_handler - ERROR - Error in weather_current: 401 Client Error: Unauthorized for url: http://api.openweathermap.org/data/2.5/weather?q=abcd&appid=your_openweather_api_key_here&units=metric
2025-08-15 03:21:13,404 - services.error_handler - ERROR - Traceback: Traceback (most recent call last):
  File "S:\capitalone\project\web_app\..\services\weather.py", line 42, in get_current_weather
    response.raise_for_status()
    ~~~~~~~~~~~~~~~~~~~~~~~~~^^
  File "S:\capitalone\project\venv\Lib\site-packages\requests\models.py", line 1026, in raise_for_status
    raise HTTPError(http_error_msg, response=self)
requests.exceptions.HTTPError: 401 Client Error: Unauthorized for url: http://api.openweathermap.org/data/2.5/weather?q=abcd&appid=your_openweather_api_key_here&units=metric

2025-08-15 03:21:13,555 - services.error_handler - ERROR - Error in weather_forecast: 401 Client Error: Unauthorized for url: http://api.openweathermap.org/data/2.5/forecast?q=abcd&appid=your_openweather_api_key_here&units=metric&cnt=40
2025-08-15 03:21:13,555 - services.error_handler - ERROR - Traceback: Traceback (most recent call last):
  File "S:\capitalone\project\web_app\..\services\weather.py", line 90, in get_weather_forecast
    response.raise_for_status()
    ~~~~~~~~~~~~~~~~~~~~~~~~~^^
  File "S:\capitalone\project\venv\Lib\site-packages\requests\models.py", line 1026, in raise_for_status
    raise HTTPError(http_error_msg, response=self)
requests.exceptions.HTTPError: 401 Client Error: Unauthorized for url: http://api.openweathermap.org/data/2.5/forecast?q=abcd&appid=your_openweather_api_key_here&units=metric&cnt=40

2025-08-15 15:27:58,644 - chromadb.telemetry.product.posthog - ERROR - Failed to send telemetry event ClientStartEvent: capture() takes 1 positional argument but 3 were given
2025-08-15 15:27:58,645 - sentence_transformers.SentenceTransformer - INFO - Use pytorch device_name: cpu
2025-08-15 15:27:58,645 - sentence_transformers.SentenceTransformer - INFO - Load pretrained SentenceTransformer: all-MiniLM-L6-v2
2025-08-15 15:28:05,796 - services.task_queue - INFO - Task queue started
2025-08-15 15:28:05,797 - services.task_queue - INFO - Periodic tasks completed at 2025-08-15 15:28:05.797530
2025-08-15 15:30:43,168 - passlib.handlers.bcrypt - WARNING - (trapped) error reading bcrypt version
Traceback (most recent call last):
  File "S:\capitalone\project\venv\Lib\site-packages\passlib\handlers\bcrypt.py", line 620, in _load_backend_mixin
    version = _bcrypt.__about__.__version__
              ^^^^^^^^^^^^^^^^^
AttributeError: module 'bcrypt' has no attribute '__about__'
2025-08-15 16:28:05,809 - services.task_queue - INFO - Periodic tasks completed at 2025-08-15 16:28:05.808972
2025-08-15 16:37:26,747 - services.task_queue - INFO - Task queue stopped
2025-08-15 16:48:16,435 - services.task_queue - INFO - Task queue started
2025-08-15 16:48:16,436 - services.task_queue - INFO - Periodic tasks completed at 2025-08-15 16:48:16.436083
2025-08-15 16:48:16,437 - services.task_queue - INFO - Task queue stopped
2025-08-15 16:48:19,664 - services.task_queue - INFO - Task queue started
2025-08-15 16:48:19,665 - services.task_queue - INFO - Periodic tasks completed at 2025-08-15 16:48:19.665491
2025-08-15 16:48:47,872 - passlib.handlers.bcrypt - WARNING - (trapped) error reading bcrypt version
Traceback (most recent call last):
  File "S:\capitalone\project\venv\Lib\site-packages\passlib\handlers\bcrypt.py", line 620, in _load_backend_mixin
    version = _bcrypt.__about__.__version__
              ^^^^^^^^^^^^^^^^^
AttributeError: module 'bcrypt' has no attribute '__about__'
2025-08-15 17:33:51,724 - services.task_queue - INFO - Task queue stopped
2025-08-15 19:24:00,976 - services.task_queue - INFO - Task queue started
2025-08-15 19:24:00,978 - services.task_queue - ERROR - Periodic tasks error: day is out of range for month
2025-08-15 19:29:08,973 - passlib.handlers.bcrypt - WARNING - (trapped) error reading bcrypt version
Traceback (most recent call last):
  File "S:\capitalone\project\venv\Lib\site-packages\passlib\handlers\bcrypt.py", line 620, in _load_backend_mixin
    version = _bcrypt.__about__.__version__
              ^^^^^^^^^^^^^^^^^
AttributeError: module 'bcrypt' has no attribute '__about__'
2025-08-15 19:32:08,357 - services.task_queue - INFO - Task queue started
2025-08-15 19:32:08,359 - services.task_queue - ERROR - Periodic tasks error: day is out of range for month
2025-08-15 20:09:44,551 - services.task_queue - INFO - Task queue stopped
2025-08-15 20:09:44,615 - services.task_queue - INFO - Task queue stopped
2025-08-15 20:13:46,388 - services.task_queue - INFO - Task queue started
2025-08-15 20:13:46,389 - services.task_queue - ERROR - Periodic tasks error: day is out of range for month
2025-08-15 20:13:46,389 - services.task_queue - ERROR - Periodic tasks error: day is out of range for month
2025-08-15 20:13:57,943 - services.task_queue - INFO - Task queue stopped
2025-08-15 20:14:12,998 - services.task_queue - INFO - Task queue started
2025-08-15 20:14:12,998 - services.task_queue - INFO - Task queue started
2025-08-15 20:14:12,999 - services.task_queue - ERROR - Periodic tasks error: day is out of range for month
2025-08-15 20:14:12,999 - services.task_queue - ERROR - Periodic tasks error: day is out of range for month
2025-08-15 20:14:13,000 - services.task_queue - INFO - Task queue stopped
2025-08-15 20:14:13,000 - services.task_queue - INFO - Task queue stopped
2025-08-15 20:14:16,445 - services.task_queue - INFO - Task queue started
2025-08-15 20:14:16,445 - services.task_queue - INFO - Task queue started
2025-08-15 20:14:16,446 - services.task_queue - ERROR - Periodic tasks error: day is out of range for month
2025-08-15 20:22:24,055 - services.task_queue - INFO - Task queue stopped
2025-08-15 20:22:24,086 - services.task_queue - INFO - Task queue stopped
2025-08-15 20:22:27,870 - services.task_queue - INFO - Task queue started
2025-08-15 20:22:27,870 - services.task_queue - INFO - Task queue started
2025-08-15 20:22:27,871 - services.task_queue - ERROR - Periodic tasks error: day is out of range for month
2025-08-15 20:22:27,871 - services.task_queue - ERROR - Periodic tasks error: day is out of range for month
2025-08-15 20:22:27,872 - services.task_queue - INFO - Task queue stopped
2025-08-15 20:22:27,872 - services.task_queue - INFO - Task queue stopped
2025-08-15 20:22:31,307 - services.task_queue - INFO - Task queue started
2025-08-15 20:22:31,308 - services.task_queue - ERROR - Periodic tasks error: day is out of range for month
2025-08-15 20:22:31,309 - services.task_queue - INFO - Task queue started
2025-08-15 20:22:31,310 - services.task_queue - ERROR - Periodic tasks error: day is out of range for month
2025-08-15 20:23:52,972 - services.task_queue - INFO - Task queue stopped
2025-08-15 20:40:19,737 - services.task_queue - INFO - Task queue started
2025-08-15 20:40:19,738 - services.task_queue - ERROR - Periodic tasks error: day is out of range for month
2025-08-15 20:46:33,625 - passlib.handlers.bcrypt - WARNING - (trapped) error reading bcrypt version
Traceback (most recent call last):
  File "S:\capitalone\project\venv\Lib\site-packages\passlib\handlers\bcrypt.py", line 620, in _load_backend_mixin
    version = _bcrypt.__about__.__version__
              ^^^^^^^^^^^^^^^^^
AttributeError: module 'bcrypt' has no attribute '__about__'
2025-08-15 21:33:27,497 - services.task_queue - INFO - Task queue stopped
2025-08-15 22:29:52,759 - services.task_queue - INFO - Task queue started
2025-08-15 22:29:52,760 - services.task_queue - ERROR - Periodic tasks error: day is out of range for month
2025-08-15 22:31:43,431 - services.task_queue - INFO - Task queue stopped
2025-08-15 22:33:26,020 - services.task_queue - INFO - Task queue started
2025-08-15 22:33:26,022 - services.task_queue - ERROR - Periodic tasks error: day is out of range for month
2025-08-15 22:34:46,510 - services.task_queue - INFO - Task queue stopped
2025-08-15 23:03:14,113 - services.task_queue - INFO - Task queue started
2025-08-15 23:03:14,115 - services.task_queue - ERROR - Periodic tasks error: day is out of range for month
2025-08-15 23:04:14,040 - services.task_queue - INFO - Task queue stopped
2025-08-15 23:06:28,140 - services.task_queue - INFO - Task queue started
2025-08-15 23:06:28,141 - services.task_queue - ERROR - Periodic tasks error: day is out of range for month
2025-08-15 23:09:51,939 - services.task_queue - INFO - Task queue stopped
2025-08-15 23:09:56,323 - services.task_queue - INFO - Task queue started
2025-08-15 23:09:56,325 - services.task_queue - ERROR - Periodic tasks error: day is out of range for month
2025-08-15 23:11:02,775 - services.task_queue - INFO - Task queue stopped
2025-08-15 23:11:06,325 - services.task_queue - INFO - Task queue started
2025-08-15 23:11:06,326 - services.task_queue - ERROR - Periodic tasks error: day is out of range for month
2025-08-15 23:11:24,031 - passlib.handlers.bcrypt - WARNING - (trapped) error reading bcrypt version
Traceback (most recent call last):
  File "S:\capitalone\project\venv\Lib\site-packages\passlib\handlers\bcrypt.py", line 620, in _load_backend_mixin
    version = _bcrypt.__about__.__version__
              ^^^^^^^^^^^^^^^^^
AttributeError: module 'bcrypt' has no attribute '__about__'
2025-08-15 23:11:44,858 - services.task_queue - INFO - Task queue stopped
2025-08-15 23:11:50,107 - services.task_queue - INFO - Task queue started
2025-08-15 23:11:50,109 - services.task_queue - ERROR - Periodic tasks error: day is out of range for month
2025-08-15 23:18:42,043 - services.task_queue - INFO - Task queue stopped
2025-08-15 23:18:42,072 - services.task_queue - INFO - Task queue started
2025-08-15 23:18:42,076 - services.task_queue - ERROR - Periodic tasks error: day is out of range for month
2025-08-15 23:18:42,078 - services.task_queue - INFO - Task queue stopped
2025-08-15 23:19:35,229 - services.task_queue - INFO - Task queue started
2025-08-15 23:19:35,231 - services.task_queue - ERROR - Periodic tasks error: day is out of range for month
2025-08-15 23:26:39,164 - services.task_queue - INFO - Task queue started
2025-08-15 23:26:39,165 - services.task_queue - ERROR - Periodic tasks error: day is out of range for month
2025-08-15 23:26:39,166 - services.task_queue - INFO - Task queue stopped
2025-08-15 23:38:35,507 - services.task_queue - INFO - Task queue started
2025-08-15 23:38:35,508 - services.task_queue - ERROR - Periodic tasks error: day is out of range for month
2025-08-15 23:39:04,845 - services.task_queue - INFO - Task queue stopped
2025-08-15 23:42:28,900 - services.task_queue - INFO - Task queue stopped
2025-08-15 23:42:53,533 - services.task_queue - INFO - Task queue started
2025-08-15 23:42:53,534 - services.task_queue - ERROR - Periodic tasks error: day is out of range for month
2025-08-15 23:43:56,659 - services.task_queue - INFO - Task queue stopped
2025-08-15 23:47:27,263 - services.task_queue - INFO - Task queue started
2025-08-15 23:47:27,264 - services.task_queue - ERROR - Periodic tasks error: day is out of range for month
2025-08-15 23:48:42,234 - services.task_queue - INFO - Task queue stopped
2025-08-15 23:49:13,179 - services.task_queue - INFO - Task queue started
2025-08-15 23:49:13,181 - services.task_queue - ERROR - Periodic tasks error: day is out of range for month
2025-08-15 23:49:56,595 - services.task_queue - INFO - Task queue stopped
2025-08-15 23:51:42,190 - services.task_queue - INFO - Task queue started
2025-08-15 23:51:42,191 - services.task_queue - ERROR - Periodic tasks error: day is out of range for month
2025-08-15 23:51:45,686 - services.task_queue - INFO - Task queue stopped
2025-08-15 23:52:01,071 - services.task_queue - INFO - Task queue started
2025-08-15 23:52:01,073 - services.task_queue - ERROR - Periodic tasks error: day is out of range for month
2025-08-15 23:52:30,914 - services.task_queue - INFO - Task queue stopped
2025-08-15 23:56:12,055 - services.task_queue - INFO - Task queue started
2025-08-15 23:56:12,056 - services.task_queue - ERROR - Periodic tasks error: day is out of range for month
2025-08-15 23:56:30,657 - services.task_queue - INFO - Task queue stopped
2025-08-15 23:57:10,357 - services.task_queue - INFO - Task queue started
2025-08-15 23:57:10,359 - services.task_queue - ERROR - Periodic tasks error: day is out of range for month
2025-08-15 23:57:54,143 - services.task_queue - INFO - Task queue stopped
2025-08-15 23:59:03,218 - services.task_queue - INFO - Task queue started
2025-08-15 23:59:03,220 - services.task_queue - ERROR - Periodic tasks error: day is out of range for month
2025-08-15 23:59:22,931 - services.task_queue - INFO - Task queue stopped
2025-08-16 00:03:35,903 - services.task_queue - INFO - Task queue started
2025-08-16 00:03:35,904 - services.task_queue - ERROR - Periodic tasks error: day is out of range for month
2025-08-16 00:05:17,886 - services.task_queue - INFO - Task queue stopped
2025-08-16 00:36:08,024 - services.task_queue - INFO - Task queue started
2025-08-16 00:36:08,025 - services.task_queue - ERROR - Periodic tasks error: day is out of range for month
2025-08-16 00:36:51,919 - passlib.handlers.bcrypt - WARNING - (trapped) error reading bcrypt version
Traceback (most recent call last):
  File "S:\capitalone\project\venv\Lib\site-packages\passlib\handlers\bcrypt.py", line 620, in _load_backend_mixin
    version = _bcrypt.__about__.__version__
              ^^^^^^^^^^^^^^^^^
AttributeError: module 'bcrypt' has no attribute '__about__'
2025-08-16 00:49:22,021 - services.task_queue - INFO - Task queue stopped
