2025-08-15 03:02:50,355 - chromadb.telemetry.product.posthog - ERROR - Failed to send telemetry event ClientStartEvent: capture() takes 1 positional argument but 3 were given
2025-08-15 03:02:50,356 - sentence_transformers.SentenceTransformer - INFO - Use pytorch device_name: cpu
2025-08-15 03:02:50,357 - sentence_transformers.SentenceTransformer - INFO - Load pretrained SentenceTransformer: all-MiniLM-L6-v2
2025-08-15 03:02:55,980 - chromadb.telemetry.product.posthog - ERROR - Failed to send telemetry event ClientCreateCollectionEvent: capture() takes 1 positional argument but 3 were given
2025-08-15 03:02:55,992 - chromadb.telemetry.product.posthog - ERROR - Failed to send telemetry event ClientCreateCollectionEvent: capture() takes 1 positional argument but 3 were given
2025-08-15 03:02:56,005 - chromadb.telemetry.product.posthog - ERROR - Failed to send telemetry event ClientCreateCollectionEvent: capture() takes 1 positional argument but 3 were given
2025-08-15 03:02:56,421 - chromadb.telemetry.product.posthog - ERROR - Failed to send telemetry event CollectionAddEvent: capture() takes 1 positional argument but 3 were given
2025-08-15 03:02:56,598 - chromadb.telemetry.product.posthog - ERROR - Failed to send telemetry event CollectionAddEvent: capture() takes 1 positional argument but 3 were given
2025-08-15 03:04:45,145 - chromadb.telemetry.product.posthog - ERROR - Failed to send telemetry event ClientStartEvent: capture() takes 1 positional argument but 3 were given
2025-08-15 03:04:45,146 - sentence_transformers.SentenceTransformer - INFO - Use pytorch device_name: cpu
2025-08-15 03:04:45,147 - sentence_transformers.SentenceTransformer - INFO - Load pretrained SentenceTransformer: all-MiniLM-L6-v2
2025-08-15 03:05:37,570 - chromadb.telemetry.product.posthog - ERROR - Failed to send telemetry event ClientStartEvent: capture() takes 1 positional argument but 3 were given
2025-08-15 03:05:37,572 - sentence_transformers.SentenceTransformer - INFO - Use pytorch device_name: cpu
2025-08-15 03:05:37,572 - sentence_transformers.SentenceTransformer - INFO - Load pretrained SentenceTransformer: all-MiniLM-L6-v2
2025-08-15 03:05:42,471 - services.task_queue - INFO - Task queue started
2025-08-15 03:05:42,474 - services.task_queue - INFO - Periodic tasks completed at 2025-08-15 03:05:42.474077
2025-08-15 03:06:34,046 - passlib.handlers.bcrypt - WARNING - (trapped) error reading bcrypt version
Traceback (most recent call last):
  File "S:\capitalone\project\venv\Lib\site-packages\passlib\handlers\bcrypt.py", line 620, in _load_backend_mixin
    version = _bcrypt.__about__.__version__
              ^^^^^^^^^^^^^^^^^
AttributeError: module 'bcrypt' has no attribute '__about__'
2025-08-15 03:07:38,289 - chromadb.telemetry.product.posthog - ERROR - Failed to send telemetry event CollectionQueryEvent: capture() takes 1 positional argument but 3 were given
2025-08-15 03:07:38,361 - chromadb.telemetry.product.posthog - ERROR - Failed to send telemetry event CollectionQueryEvent: capture() takes 1 positional argument but 3 were given
2025-08-15 03:07:38,435 - chromadb.telemetry.product.posthog - ERROR - Failed to send telemetry event CollectionQueryEvent: capture() takes 1 positional argument but 3 were given
2025-08-15 03:07:41,223 - services.error_handler - ERROR - Error in weather_current: 401 Client Error: Unauthorized for url: http://api.openweathermap.org/data/2.5/weather?q=Davanagere%2C+Karnataka&appid=your_openweather_api_key_here&units=metric
2025-08-15 03:07:41,224 - services.error_handler - ERROR - Traceback: Traceback (most recent call last):
  File "S:\capitalone\project\web_app\..\services\weather.py", line 42, in get_current_weather
    response.raise_for_status()
    ~~~~~~~~~~~~~~~~~~~~~~~~~^^
  File "S:\capitalone\project\venv\Lib\site-packages\requests\models.py", line 1026, in raise_for_status
    raise HTTPError(http_error_msg, response=self)
requests.exceptions.HTTPError: 401 Client Error: Unauthorized for url: http://api.openweathermap.org/data/2.5/weather?q=Davanagere%2C+Karnataka&appid=your_openweather_api_key_here&units=metric

2025-08-15 03:07:41,416 - services.error_handler - ERROR - Error in weather_forecast: 401 Client Error: Unauthorized for url: http://api.openweathermap.org/data/2.5/forecast?q=Davanagere%2C+Karnataka&appid=your_openweather_api_key_here&units=metric&cnt=40
2025-08-15 03:07:41,417 - services.error_handler - ERROR - Traceback: Traceback (most recent call last):
  File "S:\capitalone\project\web_app\..\services\weather.py", line 90, in get_weather_forecast
    response.raise_for_status()
    ~~~~~~~~~~~~~~~~~~~~~~~~~^^
  File "S:\capitalone\project\venv\Lib\site-packages\requests\models.py", line 1026, in raise_for_status
    raise HTTPError(http_error_msg, response=self)
requests.exceptions.HTTPError: 401 Client Error: Unauthorized for url: http://api.openweathermap.org/data/2.5/forecast?q=Davanagere%2C+Karnataka&appid=your_openweather_api_key_here&units=metric&cnt=40

2025-08-15 03:20:24,813 - services.error_handler - ERROR - Error in weather_current: 401 Client Error: Unauthorized for url: http://api.openweathermap.org/data/2.5/weather?q=panjab&appid=your_openweather_api_key_here&units=metric
2025-08-15 03:20:24,813 - services.error_handler - ERROR - Traceback: Traceback (most recent call last):
  File "S:\capitalone\project\web_app\..\services\weather.py", line 42, in get_current_weather
    response.raise_for_status()
    ~~~~~~~~~~~~~~~~~~~~~~~~~^^
  File "S:\capitalone\project\venv\Lib\site-packages\requests\models.py", line 1026, in raise_for_status
    raise HTTPError(http_error_msg, response=self)
requests.exceptions.HTTPError: 401 Client Error: Unauthorized for url: http://api.openweathermap.org/data/2.5/weather?q=panjab&appid=your_openweather_api_key_here&units=metric

2025-08-15 03:20:24,994 - services.error_handler - ERROR - Error in weather_forecast: 401 Client Error: Unauthorized for url: http://api.openweathermap.org/data/2.5/forecast?q=panjab&appid=your_openweather_api_key_here&units=metric&cnt=40
2025-08-15 03:20:24,995 - services.error_handler - ERROR - Traceback: Traceback (most recent call last):
  File "S:\capitalone\project\web_app\..\services\weather.py", line 90, in get_weather_forecast
    response.raise_for_status()
    ~~~~~~~~~~~~~~~~~~~~~~~~~^^
  File "S:\capitalone\project\venv\Lib\site-packages\requests\models.py", line 1026, in raise_for_status
    raise HTTPError(http_error_msg, response=self)
requests.exceptions.HTTPError: 401 Client Error: Unauthorized for url: http://api.openweathermap.org/data/2.5/forecast?q=panjab&appid=your_openweather_api_key_here&units=metric&cnt=40

2025-08-15 03:20:44,412 - services.error_handler - ERROR - Error in weather_current: 401 Client Error: Unauthorized for url: http://api.openweathermap.org/data/2.5/weather?q=abcd&appid=your_openweather_api_key_here&units=metric
2025-08-15 03:20:44,413 - services.error_handler - ERROR - Traceback: Traceback (most recent call last):
  File "S:\capitalone\project\web_app\..\services\weather.py", line 42, in get_current_weather
    response.raise_for_status()
    ~~~~~~~~~~~~~~~~~~~~~~~~~^^
  File "S:\capitalone\project\venv\Lib\site-packages\requests\models.py", line 1026, in raise_for_status
    raise HTTPError(http_error_msg, response=self)
requests.exceptions.HTTPError: 401 Client Error: Unauthorized for url: http://api.openweathermap.org/data/2.5/weather?q=abcd&appid=your_openweather_api_key_here&units=metric

2025-08-15 03:20:44,587 - services.error_handler - ERROR - Error in weather_forecast: 401 Client Error: Unauthorized for url: http://api.openweathermap.org/data/2.5/forecast?q=abcd&appid=your_openweather_api_key_here&units=metric&cnt=40
2025-08-15 03:20:44,588 - services.error_handler - ERROR - Traceback: Traceback (most recent call last):
  File "S:\capitalone\project\web_app\..\services\weather.py", line 90, in get_weather_forecast
    response.raise_for_status()
    ~~~~~~~~~~~~~~~~~~~~~~~~~^^
  File "S:\capitalone\project\venv\Lib\site-packages\requests\models.py", line 1026, in raise_for_status
    raise HTTPError(http_error_msg, response=self)
requests.exceptions.HTTPError: 401 Client Error: Unauthorized for url: http://api.openweathermap.org/data/2.5/forecast?q=abcd&appid=your_openweather_api_key_here&units=metric&cnt=40

2025-08-15 03:21:13,403 - services.error_handler - ERROR - Error in weather_current: 401 Client Error: Unauthorized for url: http://api.openweathermap.org/data/2.5/weather?q=abcd&appid=your_openweather_api_key_here&units=metric
2025-08-15 03:21:13,404 - services.error_handler - ERROR - Traceback: Traceback (most recent call last):
  File "S:\capitalone\project\web_app\..\services\weather.py", line 42, in get_current_weather
    response.raise_for_status()
    ~~~~~~~~~~~~~~~~~~~~~~~~~^^
  File "S:\capitalone\project\venv\Lib\site-packages\requests\models.py", line 1026, in raise_for_status
    raise HTTPError(http_error_msg, response=self)
requests.exceptions.HTTPError: 401 Client Error: Unauthorized for url: http://api.openweathermap.org/data/2.5/weather?q=abcd&appid=your_openweather_api_key_here&units=metric

2025-08-15 03:21:13,555 - services.error_handler - ERROR - Error in weather_forecast: 401 Client Error: Unauthorized for url: http://api.openweathermap.org/data/2.5/forecast?q=abcd&appid=your_openweather_api_key_here&units=metric&cnt=40
2025-08-15 03:21:13,555 - services.error_handler - ERROR - Traceback: Traceback (most recent call last):
  File "S:\capitalone\project\web_app\..\services\weather.py", line 90, in get_weather_forecast
    response.raise_for_status()
    ~~~~~~~~~~~~~~~~~~~~~~~~~^^
  File "S:\capitalone\project\venv\Lib\site-packages\requests\models.py", line 1026, in raise_for_status
    raise HTTPError(http_error_msg, response=self)
requests.exceptions.HTTPError: 401 Client Error: Unauthorized for url: http://api.openweathermap.org/data/2.5/forecast?q=abcd&appid=your_openweather_api_key_here&units=metric&cnt=40

2025-08-15 15:27:58,644 - chromadb.telemetry.product.posthog - ERROR - Failed to send telemetry event ClientStartEvent: capture() takes 1 positional argument but 3 were given
2025-08-15 15:27:58,645 - sentence_transformers.SentenceTransformer - INFO - Use pytorch device_name: cpu
2025-08-15 15:27:58,645 - sentence_transformers.SentenceTransformer - INFO - Load pretrained SentenceTransformer: all-MiniLM-L6-v2
2025-08-15 15:28:05,796 - services.task_queue - INFO - Task queue started
2025-08-15 15:28:05,797 - services.task_queue - INFO - Periodic tasks completed at 2025-08-15 15:28:05.797530
2025-08-15 15:30:43,168 - passlib.handlers.bcrypt - WARNING - (trapped) error reading bcrypt version
Traceback (most recent call last):
  File "S:\capitalone\project\venv\Lib\site-packages\passlib\handlers\bcrypt.py", line 620, in _load_backend_mixin
    version = _bcrypt.__about__.__version__
              ^^^^^^^^^^^^^^^^^
AttributeError: module 'bcrypt' has no attribute '__about__'
2025-08-15 16:28:05,809 - services.task_queue - INFO - Periodic tasks completed at 2025-08-15 16:28:05.808972
2025-08-15 16:37:26,747 - services.task_queue - INFO - Task queue stopped
2025-08-15 16:48:16,435 - services.task_queue - INFO - Task queue started
2025-08-15 16:48:16,436 - services.task_queue - INFO - Periodic tasks completed at 2025-08-15 16:48:16.436083
2025-08-15 16:48:16,437 - services.task_queue - INFO - Task queue stopped
2025-08-15 16:48:19,664 - services.task_queue - INFO - Task queue started
2025-08-15 16:48:19,665 - services.task_queue - INFO - Periodic tasks completed at 2025-08-15 16:48:19.665491
2025-08-15 16:48:47,872 - passlib.handlers.bcrypt - WARNING - (trapped) error reading bcrypt version
Traceback (most recent call last):
  File "S:\capitalone\project\venv\Lib\site-packages\passlib\handlers\bcrypt.py", line 620, in _load_backend_mixin
    version = _bcrypt.__about__.__version__
              ^^^^^^^^^^^^^^^^^
AttributeError: module 'bcrypt' has no attribute '__about__'
2025-08-15 17:33:51,724 - services.task_queue - INFO - Task queue stopped
